Workbook

Sheet Start here
B2: Where You Stand: the spreadsheet
B4: 1. This workbook does four things. My investments works out what your own money has actually earned, counting the date every rupee moved. Plan my goal shows where a plan lands and what the goal needs. Index history puts the same rupees on the same dates into an index. Fund history measures a fund's own record from its NAV list.
B6: 2. Save your own copy before you type anything, so you always have a clean one.
B8: 3. On My investments, enter one row for every payment: the date, then Money in or Money out from the list, then the amount as a plain positive number. Name the holding in the last column if you hold more than one.
B10: 4. In the last row, enter today's date, choose Worth today, and type what the holding is worth now. Without that row there is no return to measure. With several holdings, give each its own Worth today row.
B12: Dates show as dd-mmm-yyyy. If a date you typed reads back as a different day, your computer is set to month-first dates; retype it the other way round, or as yyyy-mm-dd.
B14: 5. Cream cells are yours to type in. Everything else is worked out for you, and the tabs are protected without a password so nothing is overwritten by accident. To change anything else, choose Review, then Unprotect Sheet.
B16: 6. Index history: paste an index's dates and values, oldest first, and the tab puts your own rupees, on your own dates, into that index beside your result.
B18: 7. Fund history: paste a fund's dates and NAVs, oldest first, for its rolling returns over every holding period of the length you choose, its worst fall, its year-by-year record, its growth over exactly your dates, and what your units are worth at the latest NAV.
B20: 8. The Example tab is My investments already filled in, if you get stuck. How the site works each figure out is set out on its About page, under How this tool calculates.
B22: Everything here is before tax and before exit load. It measures money that has already moved and illustrates assumptions you choose yourself; it is an educational tool, not investment advice, and it recommends nothing.

Sheet My investments
B2: Fund or portfolio name | H2: Your portfolio
B3: Your XIRR | H3: You put in | I3: =Calc!$D$3 -> 0
B4: =IFERROR(XIRR(Calc!$X$7:$X$508,Calc!$Y$7:$Y$508),IFERROR(XIRR(Calc!$X$7:$X$508,Calc!$Y$7:$Y$508,-0.5),"Check the status line below")) -> Check the status line below | H4: You took out | I4: =Calc!$D$4 -> 0
B5: =IF(COUNT($B$8:$B$507)=0,"Add your first investment below.",IF(Calc!$D$1=0,"Add a last row: today's date, Worth today, and what the holding is worth now.",IF(Calc!$D$6>0,Calc!$D$6&" row(s) have an amount but no date: fill the date in or clear the amount.",IF(Calc!$D$7>0,Calc!$D$7&" row(s) have a date but no amount.",IF(ISNUMBER($B$4),"","The entries do not settle to one rate: check the dates and the Money in / Money out choices."))))) -> Add your first investment below. | H5: Worth now | I5: =Calc!$D$5 -> 0
B6: Type in the cream cells only. One row for every payment, in any order; leave no amount without its date. Money in and Money out are plain positive numbers; the sheet sets the sign. | H6: Gain or loss | I6: =Calc!$D$5+Calc!$D$4-Calc!$D$3 -> 0
B7: Date | C7: What happened | D7: Amount | E7: Used by the sheet | F7: Which holding | H7: Total return, no clock in it | I7: =IF(Calc!$D$3=0,"",(Calc!$D$5+Calc!$D$4-Calc!$D$3)/Calc!$D$3)
E8: =IF($B8="","",IF($C8="Money in",-$D8,$D8)) | H8: How long you have held it | I8: =IF(COUNT($B$8:$B$507)<2,"",(MAX($B$8:$B$507)-MIN($B$8:$B$507))/365)
E9: =IF($B9="","",IF($C9="Money in",-$D9,$D9)) | H9: Doubling time at your XIRR | I9: =IF(ISNUMBER($B$4),IF($B$4>0,LN(2)/LN(1+$B$4),""),"")
E10: =IF($B10="","",IF($C10="Money in",-$D10,$D10)) | H10: Inflation to measure against (% a year)
E11: =IF($B11="","",IF($C11="Money in",-$D11,$D11)) | H11: Return after inflation | I11: =IF(OR($I$10="",NOT(ISNUMBER($B$4))),"",(1+$B$4)/(1+$I$10/100)-1)
E12: =IF($B12="","",IF($C12="Money in",-$D12,$D12)) | H12: Type your own inflation figure; the sheet does not choose one. (1 + return) ÷ (1 + inflation) − 1, not a subtraction.
E13: =IF($B13="","",IF($C13="Money in",-$D13,$D13))
E14: =IF($B14="","",IF($C14="Money in",-$D14,$D14)) | H14: Type a holding name | I14: You put in | J14: Worth now | K14: Its own XIRR
E15: =IF($B15="","",IF($C15="Money in",-$D15,$D15)) | I15: =IF($H15="","",SUMIFS($D$8:$D$507,$F$8:$F$507,$H15,$C$8:$C$507,"Money in",$B$8:$B$507,"<>")) | J15: =IF($H15="","",SUMIFS($D$8:$D$507,$F$8:$F$507,$H15,$C$8:$C$507,"Worth today",$B$8:$B$507,"<>")) | K15: =IF($H15="","",IFERROR(XIRR(Calc!$AA$7:$AA$508,Calc!$Y$7:$Y$508),IFERROR(XIRR(Calc!$AA$7:$AA$508,Calc!$Y$7:$Y$508,-0.5),"needs its own Worth today row")))
E16: =IF($B16="","",IF($C16="Money in",-$D16,$D16)) | I16: =IF($H16="","",SUMIFS($D$8:$D$507,$F$8:$F$507,$H16,$C$8:$C$507,"Money in",$B$8:$B$507,"<>")) | J16: =IF($H16="","",SUMIFS($D$8:$D$507,$F$8:$F$507,$H16,$C$8:$C$507,"Worth today",$B$8:$B$507,"<>")) | K16: =IF($H16="","",IFERROR(XIRR(Calc!$AB$7:$AB$508,Calc!$Y$7:$Y$508),IFERROR(XIRR(Calc!$AB$7:$AB$508,Calc!$Y$7:$Y$508,-0.5),"needs its own Worth today row")))
E17: =IF($B17="","",IF($C17="Money in",-$D17,$D17)) | I17: =IF($H17="","",SUMIFS($D$8:$D$507,$F$8:$F$507,$H17,$C$8:$C$507,"Money in",$B$8:$B$507,"<>")) | J17: =IF($H17="","",SUMIFS($D$8:$D$507,$F$8:$F$507,$H17,$C$8:$C$507,"Worth today",$B$8:$B$507,"<>")) | K17: =IF($H17="","",IFERROR(XIRR(Calc!$AC$7:$AC$508,Calc!$Y$7:$Y$508),IFERROR(XIRR(Calc!$AC$7:$AC$508,Calc!$Y$7:$Y$508,-0.5),"needs its own Worth today row")))
E18: =IF($B18="","",IF($C18="Money in",-$D18,$D18)) | I18: =IF($H18="","",SUMIFS($D$8:$D$507,$F$8:$F$507,$H18,$C$8:$C$507,"Money in",$B$8:$B$507,"<>")) | J18: =IF($H18="","",SUMIFS($D$8:$D$507,$F$8:$F$507,$H18,$C$8:$C$507,"Worth today",$B$8:$B$507,"<>")) | K18: =IF($H18="","",IFERROR(XIRR(Calc!$AD$7:$AD$508,Calc!$Y$7:$Y$508),IFERROR(XIRR(Calc!$AD$7:$AD$508,Calc!$Y$7:$Y$508,-0.5),"needs its own Worth today row")))
E19: =IF($B19="","",IF($C19="Money in",-$D19,$D19)) | I19: =IF($H19="","",SUMIFS($D$8:$D$507,$F$8:$F$507,$H19,$C$8:$C$507,"Money in",$B$8:$B$507,"<>")) | J19: =IF($H19="","",SUMIFS($D$8:$D$507,$F$8:$F$507,$H19,$C$8:$C$507,"Worth today",$B$8:$B$507,"<>")) | K19: =IF($H19="","",IFERROR(XIRR(Calc!$AE$7:$AE$508,Calc!$Y$7:$Y$508),IFERROR(XIRR(Calc!$AE$7:$AE$508,Calc!$Y$7:$Y$508,-0.5),"needs its own Worth today row")))
E20: =IF($B20="","",IF($C20="Money in",-$D20,$D20)) | I20: =IF($H20="","",SUMIFS($D$8:$D$507,$F$8:$F$507,$H20,$C$8:$C$507,"Money in",$B$8:$B$507,"<>")) | J20: =IF($H20="","",SUMIFS($D$8:$D$507,$F$8:$F$507,$H20,$C$8:$C$507,"Worth today",$B$8:$B$507,"<>")) | K20: =IF($H20="","",IFERROR(XIRR(Calc!$AF$7:$AF$508,Calc!$Y$7:$Y$508),IFERROR(XIRR(Calc!$AF$7:$AF$508,Calc!$Y$7:$Y$508,-0.5),"needs its own Worth today row")))
E21: =IF($B21="","",IF($C21="Money in",-$D21,$D21)) | I21: =IF($H21="","",SUMIFS($D$8:$D$507,$F$8:$F$507,$H21,$C$8:$C$507,"Money in",$B$8:$B$507,"<>")) | J21: =IF($H21="","",SUMIFS($D$8:$D$507,$F$8:$F$507,$H21,$C$8:$C$507,"Worth today",$B$8:$B$507,"<>")) | K21: =IF($H21="","",IFERROR(XIRR(Calc!$AG$7:$AG$508,Calc!$Y$7:$Y$508),IFERROR(XIRR(Calc!$AG$7:$AG$508,Calc!$Y$7:$Y$508,-0.5),"needs its own Worth today row")))
E22: =IF($B22="","",IF($C22="Money in",-$D22,$D22)) | I22: =IF($H22="","",SUMIFS($D$8:$D$507,$F$8:$F$507,$H22,$C$8:$C$507,"Money in",$B$8:$B$507,"<>")) | J22: =IF($H22="","",SUMIFS($D$8:$D$507,$F$8:$F$507,$H22,$C$8:$C$507,"Worth today",$B$8:$B$507,"<>")) | K22: =IF($H22="","",IFERROR(XIRR(Calc!$AH$7:$AH$508,Calc!$Y$7:$Y$508),IFERROR(XIRR(Calc!$AH$7:$AH$508,Calc!$Y$7:$Y$508,-0.5),"needs its own Worth today row")))
E23: =IF($B23="","",IF($C23="Money in",-$D23,$D23)) | I23: =IF($H23="","",SUMIFS($D$8:$D$507,$F$8:$F$507,$H23,$C$8:$C$507,"Money in",$B$8:$B$507,"<>")) | J23: =IF($H23="","",SUMIFS($D$8:$D$507,$F$8:$F$507,$H23,$C$8:$C$507,"Worth today",$B$8:$B$507,"<>")) | K23: =IF($H23="","",IFERROR(XIRR(Calc!$AI$7:$AI$508,Calc!$Y$7:$Y$508),IFERROR(XIRR(Calc!$AI$7:$AI$508,Calc!$Y$7:$Y$508,-0.5),"needs its own Worth today row")))
E24: =IF($B24="","",IF($C24="Money in",-$D24,$D24)) | I24: =IF($H24="","",SUMIFS($D$8:$D$507,$F$8:$F$507,$H24,$C$8:$C$507,"Money in",$B$8:$B$507,"<>")) | J24: =IF($H24="","",SUMIFS($D$8:$D$507,$F$8:$F$507,$H24,$C$8:$C$507,"Worth today",$B$8:$B$507,"<>")) | K24: =IF($H24="","",IFERROR(XIRR(Calc!$AJ$7:$AJ$508,Calc!$Y$7:$Y$508),IFERROR(XIRR(Calc!$AJ$7:$AJ$508,Calc!$Y$7:$Y$508,-0.5),"needs its own Worth today row")))
E25: =IF($B25="","",IF($C25="Money in",-$D25,$D25))
E26: =IF($B26="","",IF($C26="Money in",-$D26,$D26)) | H26: Leave the names blank if you hold only one thing. Each named holding needs its own Worth today row, tagged with its name.
E27: =IF($B27="","",IF($C27="Money in",-$D27,$D27)) | H27: Your portfolio XIRR is not the average of these: it weighs each holding by how much money you actually had in it, and for how long.
E28: =IF($B28="","",IF($C28="Money in",-$D28,$D28)) | H28: Every figure is before tax and exit load. XIRR is the one yearly rate at which every entry, discounted from its own date on a 365-day year, adds up to zero; a spreadsheet's XIRR and this site use the same convention.
E29: =IF($B29="","",IF($C29="Money in",-$D29,$D29))
E30: =IF($B30="","",IF($C30="Money in",-$D30,$D30))
E31: =IF($B31="","",IF($C31="Money in",-$D31,$D31))
E32: =IF($B32="","",IF($C32="Money in",-$D32,$D32))
E33: =IF($B33="","",IF($C33="Money in",-$D33,$D33))
E34: =IF($B34="","",IF($C34="Money in",-$D34,$D34))
E35: =IF($B35="","",IF($C35="Money in",-$D35,$D35))
E36: =IF($B36="","",IF($C36="Money in",-$D36,$D36))
E37: =IF($B37="","",IF($C37="Money in",-$D37,$D37))
E38: =IF($B38="","",IF($C38="Money in",-$D38,$D38))
E39: =IF($B39="","",IF($C39="Money in",-$D39,$D39))
E40: =IF($B40="","",IF($C40="Money in",-$D40,$D40))
... E507: =IF($B507="","",IF($C507="Money in",-$D507,$D507))

Sheet Plan my goal
A1: Plan my goal
A2: Type the cream cells. Whole years only, 1 to 50. The return is an assumption you choose; nobody can promise it.
A4: Amount you are aiming for (₹) | B4: 10000000
A5: What you have already (₹) | B5: 400000
A6: Years left (whole years) | B6: 15
A7: Investing each month now (₹) | B7: 10000
A8: Assumed return each year (%) | B8: 10 | C8: An assumption you choose. Nobody can promise it.
A9: Raise the monthly amount each year by (%) | B9: 0
A10: Inflation, if you want the goal in today's rupees (%) | C10: Optional. Leave blank to skip.
A12: If nothing changes, you reach | B12: =IF(Calc!$G$10=0,"Check the line below",Calc!$G$11+Calc!$G$12) -> 5687111.4
A13: =IF($B$6="","Enter how many years are left.",IF(OR($B$6<1,$B$6>50,$B$6<>INT($B$6)),"Years left must be a whole number from 1 to 50.",IF($B$4="","Enter the amount you are aiming for.",IF($B$4<=0,"The amount you are aiming for must be more than zero.",IF($B$8="","Enter the return you assume.",IF(OR($B$8<0,$B$8>50),"Assume a return between 0% and 50% a year.",""))))))
A15: Against your goal | B15: =IF(Calc!$G$10=0,"",ABS(Calc!$G$13)) -> 4312888.6 | C15: =IF(Calc!$G$10=0,"",IF(Calc!$G$13>0.5,"short","to spare")) -> short
A16: Extra each month to close it | B16: =IF(Calc!$G$10=0,"",Calc!$G$14) -> 10738.697 | C16: On top of what you already invest each month.
A18: Where that comes from
A19: What you already have, grown | B19: =IF(Calc!$G$10=0,"",Calc!$G$11) -> 1670899.3
A20: What your monthly investing adds | B20: =IF(Calc!$G$10=0,"",Calc!$G$12) -> 4016212.2
A21: Your own money paid in over the years | B21: =IF(Calc!$G$10=0,"",Calc!$G$15) -> 1800000
A22: Growth on both | B22: =IF(Calc!$G$10=0,"",Calc!$G$11+Calc!$G$12-Calc!$G$15-IF($B$5="",0,$B$5)) -> 3487111.4
A24: What it would take
A25: The return this goal needs, a year | B25: =IF(Calc!$G$10=0,"",IF(Calc!$H$41="none","reached even at no return",IF(Calc!$H$41="high","more than 50% a year",Calc!$H$82))) -> 0.15587372 | C25: =IF(Calc!$G$10=0,"","You assumed "&TEXT($B$8/100,"0.0%")&". The gap is the return you are hoping the market supplies.") -> You assumed 10.0%. The gap is the return you are hoping the market supplies.
A26: Doubling time at the return you assumed | B26: =IF(Calc!$G$10=0,"",IF(Calc!$G$1<=0,"never",LN(2)/LN(1+Calc!$G$1))) -> 7.2725409
A28: It depends what the market does | B28: You reach | C28: Extra needed each month
A29: If returns average 6% a year | B29: =IF(Calc!$G$10=0,"",Calc!$M$20) -> 3841707.9 | C29: =IF(Calc!$G$10=0,"",IF(Calc!$N$20<=0,"nothing more",Calc!$N$20)) -> 21360.081
A30: If returns average 8% a year | B30: =IF(Calc!$G$10=0,"",Calc!$M$21) -> 4666652.4 | C30: =IF(Calc!$G$10=0,"",IF(Calc!$N$21<=0,"nothing more",Calc!$N$21)) -> 15696.544
A31: If returns average 10% a year | B31: =IF(Calc!$G$10=0,"",Calc!$M$22) -> 5687111.4 | C31: =IF(Calc!$G$10=0,"",IF(Calc!$N$22<=0,"nothing more",Calc!$N$22)) -> 10738.697
A32: If returns average 12% a year | B32: =IF(Calc!$G$10=0,"",Calc!$M$23) -> 6948740.3 | C32: =IF(Calc!$G$10=0,"",IF(Calc!$N$23<=0,"nothing more",Calc!$N$23)) -> 6411.1334
A33: Nobody can tell you which of these rows the future will resemble.
A35: If you did a little more | B35: You reach | C35: Against your goal
A36: Carry on exactly as you are | B36: =IF(Calc!$G$10=0,"",Calc!$G$16) -> 5687111.4 | C36: =IF(Calc!$G$10=0,"",IF(Calc!$G$16>=$B$4,"covered, "&TEXT(Calc!$G$16-$B$4,"#,##0")&" to spare","short by "&TEXT($B$4-Calc!$G$16,"#,##0"))) -> short by 4,312,889
A37: Add ₹2,000 a month | B37: =IF(Calc!$G$10=0,"",Calc!$G$17) -> 6490353.9 | C37: =IF(Calc!$G$10=0,"",IF(Calc!$G$17>=$B$4,"covered, "&TEXT(Calc!$G$17-$B$4,"#,##0")&" to spare","short by "&TEXT($B$4-Calc!$G$17,"#,##0"))) -> short by 3,509,646
A38: Add ₹5,000 a month | B38: =IF(Calc!$G$10=0,"",Calc!$G$18) -> 7695217.5 | C38: =IF(Calc!$G$10=0,"",IF(Calc!$G$18>=$B$4,"covered, "&TEXT(Calc!$G$18-$B$4,"#,##0")&" to spare","short by "&TEXT($B$4-Calc!$G$18,"#,##0"))) -> short by 2,304,782
A39: Same amount, raised 10% every year | B39: =IF(Calc!$G$10=0,"",Calc!$G$19) -> 8871261.8 | C39: =IF(Calc!$G$10=0,"",IF(Calc!$G$19>=$B$4,"covered, "&TEXT(Calc!$G$19-$B$4,"#,##0")&" to spare","short by "&TEXT($B$4-Calc!$G$19,"#,##0"))) -> short by 1,128,738
A41: The goal in today's rupees
A42: What your target buys, in today's money | B42: =IF(Calc!$G$10=0,"",IF($B$10="","type an inflation figure in B10",$B$4/(1+$B$10/100)^$B$6)) -> type an inflation figure in B10
A43: To keep today's buying power, aim for | B43: =IF(Calc!$G$10=0,"",IF($B$10="","",$B$4*(1+$B$10/100)^$B$6)) | C43: Then type that figure in B4 to see what it takes.
A45: Every line above uses the return you typed in. It is an assumption, not a forecast, and it leaves out tax and exit loads.
A46: Real markets do not deliver the same return every year, and a run of poor years early on hurts more than the same years late.
A47: Each month's instalment is added at the start of the month and earns from then; the step-up applies once a year. The site's Plan my goal screen uses the same arithmetic.

Sheet Index history
A1: Index history: the same rupees, on the same dates, in an index
A2: Paste the index's dates in column A and its values in column B, oldest first, one row per day. Use the total return index (TRI) where one is published; a price index leaves dividends out. Up to 5,000 rows.
A3: Every payment on My investments then buys units of this index at its value on that date, every withdrawal sells them, and the units left are valued on your Worth today date. The XIRR of those flows is what the same rupees would have earned in the index.
A7: Date | B7: Index value | D7: The same rupees, on the same dates, in this index
D8: Your XIRR | E8: ='My investments'!$B$4 -> Check the status line below
D9: In the index | E9: =IF(Calc!$D$10=0,"paste the index",IF(NOT(ISNUMBER('My investments'!$B$4)),"finish My investments first",IF(Calc!$D$12>0,Calc!$D$12&" of your payment dates fall outside the index",IF(Calc!$D$16=1,"the index ends more than a week before your Worth today date",IFERROR(XIRR(Calc!$Z$7:$Z$508,Calc!$Y$7:$Y$508),IFERROR(XIRR(Calc!$Z$7:$Z$508,Calc!$Y$7:$Y$508,-0.5),"no rate")))))) -> paste the index
D10: Your gain | E10: =IF(ISNUMBER($E$9),'My investments'!$I$6,"")
D11: Index gain | E11: =IF(ISNUMBER($E$9),Calc!$Z$508+Calc!$D$4-Calc!$D$3,"")
D12: Your money ran, a year | E12: =IF(ISNUMBER($E$9),'My investments'!$B$4-$E$9,"")
D13: Positive: ahead of the index. Both figures share your dates, so the difference is what your fund did with your money, not when you gave it. The index carries no costs and cannot be bought as it stands.
D15: Rows pasted | E15: =Calc!$D$10 -> 0
D16: Dates in order, oldest first? | E16: =IF(Calc!$D$10=0,"",IF(SUMPRODUCT(($A$9:$A$5007<>"")*($A$9:$A$5007<$A$8:$A$5006))>0,"No: sort them oldest to newest","Yes"))
D17: Dates read as text, not dates | E17: =SUMPRODUCT(--ISTEXT($A$8:$A$5007)) -> 0
D18: If that count is not zero, the pasted dates were not recognised: in Excel use Data, Text to Columns, and choose the date order; in Google Sheets, Format, Number, Date.
D20: Units of the index your rupees bought, net | E20: =IF(ISNUMBER($E$9),Calc!$D$13,"")
D21: Valued on the index date | E21: =IF(ISNUMBER($E$9),Calc!$D$17,"")
D22: At an index value of | E22: =IF(ISNUMBER($E$9),Calc!$D$14,"")

Sheet Fund history
A1: Fund history: the fund's own record, from its NAV list
A2: Paste the fund's dates in column A and its NAVs in column B, oldest first, one row per day, up to 5,000 rows (about twenty years). Use the Growth option's NAV; an IDCW option's NAV drops at every payout.
D4: Holding period, years | E4: 5
D5: Rate to compare against, % a year | E5: 8
D6: Units you hold, if you want their value
A7: Date | B7: NAV | K7: Window end | L7: Row | M7: Ended on | N7: End NAV | O7: Return a year | P7: High so far | Q7: Below high
D8: =IF($E$4="","Rolling returns","Rolling returns over every "&$E$4&"-year holding period") -> Rolling returns over every 5-year holding period | K8: =IF($A8="","",EDATE($A8,12*$E$4)) | L8: =IF($K8="","",IF($K8>MAX($A$8:$A$5007),"",IFERROR(MATCH($K8,$A$8:$A$5007,1),""))) | M8: =IF($L8="","",INDEX($A$8:$A$5007,$L8)) | N8: =IF($L8="","",INDEX($B$8:$B$5007,$L8)) | O8: =IF($M8="","",IF($K8-$M8>7,"",IF($M8<=$A8,"",IF(OR($B8<=0,$N8<=0),"",($N8/$B8)^(365/($M8-$A8))-1)))) | P8: =IF($B8="","",$B8) | Q8: =IF($P8="","",$B8/$P8-1)
D9: Holding periods measured | E9: =COUNT($O$8:$O$5007) -> 0 | K9: =IF($A9="","",EDATE($A9,12*$E$4)) | L9: =IF($K9="","",IF($K9>MAX($A$8:$A$5007),"",IFERROR(MATCH($K9,$A$8:$A$5007,1),""))) | M9: =IF($L9="","",INDEX($A$8:$A$5007,$L9)) | N9: =IF($L9="","",INDEX($B$8:$B$5007,$L9)) | O9: =IF($M9="","",IF($K9-$M9>7,"",IF($M9<=$A9,"",IF(OR($B9<=0,$N9<=0),"",($N9/$B9)^(365/($M9-$A9))-1)))) | P9: =IF($B9="","",IF($P8="",$B9,MAX($P8,$B9))) | Q9: =IF($P9="","",$B9/$P9-1)
D10: Worst | E10: =IF($E$9=0,"",MIN($O$8:$O$5007)) | K10: =IF($A10="","",EDATE($A10,12*$E$4)) | L10: =IF($K10="","",IF($K10>MAX($A$8:$A$5007),"",IFERROR(MATCH($K10,$A$8:$A$5007,1),""))) | M10: =IF($L10="","",INDEX($A$8:$A$5007,$L10)) | N10: =IF($L10="","",INDEX($B$8:$B$5007,$L10)) | O10: =IF($M10="","",IF($K10-$M10>7,"",IF($M10<=$A10,"",IF(OR($B10<=0,$N10<=0),"",($N10/$B10)^(365/($M10-$A10))-1)))) | P10: =IF($B10="","",IF($P9="",$B10,MAX($P9,$B10))) | Q10: =IF($P10="","",$B10/$P10-1)
D11: Median: half did better, half worse | E11: =IF($E$9=0,"",MEDIAN($O$8:$O$5007)) | K11: =IF($A11="","",EDATE($A11,12*$E$4)) | L11: =IF($K11="","",IF($K11>MAX($A$8:$A$5007),"",IFERROR(MATCH($K11,$A$8:$A$5007,1),""))) | M11: =IF($L11="","",INDEX($A$8:$A$5007,$L11)) | N11: =IF($L11="","",INDEX($B$8:$B$5007,$L11)) | O11: =IF($M11="","",IF($K11-$M11>7,"",IF($M11<=$A11,"",IF(OR($B11<=0,$N11<=0),"",($N11/$B11)^(365/($M11-$A11))-1)))) | P11: =IF($B11="","",IF($P10="",$B11,MAX($P10,$B11))) | Q11: =IF($P11="","",$B11/$P11-1)
D12: Best | E12: =IF($E$9=0,"",MAX($O$8:$O$5007)) | K12: =IF($A12="","",EDATE($A12,12*$E$4)) | L12: =IF($K12="","",IF($K12>MAX($A$8:$A$5007),"",IFERROR(MATCH($K12,$A$8:$A$5007,1),""))) | M12: =IF($L12="","",INDEX($A$8:$A$5007,$L12)) | N12: =IF($L12="","",INDEX($B$8:$B$5007,$L12)) | O12: =IF($M12="","",IF($K12-$M12>7,"",IF($M12<=$A12,"",IF(OR($B12<=0,$N12<=0),"",($N12/$B12)^(365/($M12-$A12))-1)))) | P12: =IF($B12="","",IF($P11="",$B12,MAX($P11,$B12))) | Q12: =IF($P12="","",$B12/$P12-1)
D13: Ended below zero | E13: =IF($E$9=0,"",COUNTIF($O$8:$O$5007,"<0")/$E$9) | K13: =IF($A13="","",EDATE($A13,12*$E$4)) | L13: =IF($K13="","",IF($K13>MAX($A$8:$A$5007),"",IFERROR(MATCH($K13,$A$8:$A$5007,1),""))) | M13: =IF($L13="","",INDEX($A$8:$A$5007,$L13)) | N13: =IF($L13="","",INDEX($B$8:$B$5007,$L13)) | O13: =IF($M13="","",IF($K13-$M13>7,"",IF($M13<=$A13,"",IF(OR($B13<=0,$N13<=0),"",($N13/$B13)^(365/($M13-$A13))-1)))) | P13: =IF($B13="","",IF($P12="",$B13,MAX($P12,$B13))) | Q13: =IF($P13="","",$B13/$P13-1)
D14: Beat the rate in E5 | E14: =IF(OR($E$9=0,$E$5=""),"",COUNTIF($O$8:$O$5007,">"&$E$5/100)/$E$9) | K14: =IF($A14="","",EDATE($A14,12*$E$4)) | L14: =IF($K14="","",IF($K14>MAX($A$8:$A$5007),"",IFERROR(MATCH($K14,$A$8:$A$5007,1),""))) | M14: =IF($L14="","",INDEX($A$8:$A$5007,$L14)) | N14: =IF($L14="","",INDEX($B$8:$B$5007,$L14)) | O14: =IF($M14="","",IF($K14-$M14>7,"",IF($M14<=$A14,"",IF(OR($B14<=0,$N14<=0),"",($N14/$B14)^(365/($M14-$A14))-1)))) | P14: =IF($B14="","",IF($P13="",$B14,MAX($P13,$B14))) | Q14: =IF($P14="","",$B14/$P14-1)
D15: Every row is a start date; the window ends on the same calendar date years later, or the last value up to seven days before it, annualised on a 365-day year. Overlapping windows, not independent results; past periods, not future odds. | K15: =IF($A15="","",EDATE($A15,12*$E$4)) | L15: =IF($K15="","",IF($K15>MAX($A$8:$A$5007),"",IFERROR(MATCH($K15,$A$8:$A$5007,1),""))) | M15: =IF($L15="","",INDEX($A$8:$A$5007,$L15)) | N15: =IF($L15="","",INDEX($B$8:$B$5007,$L15)) | O15: =IF($M15="","",IF($K15-$M15>7,"",IF($M15<=$A15,"",IF(OR($B15<=0,$N15<=0),"",($N15/$B15)^(365/($M15-$A15))-1)))) | P15: =IF($B15="","",IF($P14="",$B15,MAX($P14,$B15))) | Q15: =IF($P15="","",$B15/$P15-1)
K16: =IF($A16="","",EDATE($A16,12*$E$4)) | L16: =IF($K16="","",IF($K16>MAX($A$8:$A$5007),"",IFERROR(MATCH($K16,$A$8:$A$5007,1),""))) | M16: =IF($L16="","",INDEX($A$8:$A$5007,$L16)) | N16: =IF($L16="","",INDEX($B$8:$B$5007,$L16)) | O16: =IF($M16="","",IF($K16-$M16>7,"",IF($M16<=$A16,"",IF(OR($B16<=0,$N16<=0),"",($N16/$B16)^(365/($M16-$A16))-1)))) | P16: =IF($B16="","",IF($P15="",$B16,MAX($P15,$B16))) | Q16: =IF($P16="","",$B16/$P16-1)
D17: The worst fall along the way | K17: =IF($A17="","",EDATE($A17,12*$E$4)) | L17: =IF($K17="","",IF($K17>MAX($A$8:$A$5007),"",IFERROR(MATCH($K17,$A$8:$A$5007,1),""))) | M17: =IF($L17="","",INDEX($A$8:$A$5007,$L17)) | N17: =IF($L17="","",INDEX($B$8:$B$5007,$L17)) | O17: =IF($M17="","",IF($K17-$M17>7,"",IF($M17<=$A17,"",IF(OR($B17<=0,$N17<=0),"",($N17/$B17)^(365/($M17-$A17))-1)))) | P17: =IF($B17="","",IF($P16="",$B17,MAX($P16,$B17))) | Q17: =IF($P17="","",$B17/$P17-1)
D18: Deepest fall from a high | E18: =IF(COUNT($B$8:$B$5007)<2,"",MIN($Q$8:$Q$5007)) | K18: =IF($A18="","",EDATE($A18,12*$E$4)) | L18: =IF($K18="","",IF($K18>MAX($A$8:$A$5007),"",IFERROR(MATCH($K18,$A$8:$A$5007,1),""))) | M18: =IF($L18="","",INDEX($A$8:$A$5007,$L18)) | N18: =IF($L18="","",INDEX($B$8:$B$5007,$L18)) | O18: =IF($M18="","",IF($K18-$M18>7,"",IF($M18<=$A18,"",IF(OR($B18<=0,$N18<=0),"",($N18/$B18)^(365/($M18-$A18))-1)))) | P18: =IF($B18="","",IF($P17="",$B18,MAX($P17,$B18))) | Q18: =IF($P18="","",$B18/$P18-1)
D19: At its bottom on | E19: =IF(NOT(ISNUMBER($E$18)),"",INDEX($A$8:$A$5007,MATCH($E$18,$Q$8:$Q$5007,0))) | K19: =IF($A19="","",EDATE($A19,12*$E$4)) | L19: =IF($K19="","",IF($K19>MAX($A$8:$A$5007),"",IFERROR(MATCH($K19,$A$8:$A$5007,1),""))) | M19: =IF($L19="","",INDEX($A$8:$A$5007,$L19)) | N19: =IF($L19="","",INDEX($B$8:$B$5007,$L19)) | O19: =IF($M19="","",IF($K19-$M19>7,"",IF($M19<=$A19,"",IF(OR($B19<=0,$N19<=0),"",($N19/$B19)^(365/($M19-$A19))-1)))) | P19: =IF($B19="","",IF($P18="",$B19,MAX($P18,$B19))) | Q19: =IF($P19="","",$B19/$P19-1)
D20: A return says what was earned; this says what had to be sat through to earn it. Whoever sells at the bottom turns the dip into a permanent result. | K20: =IF($A20="","",EDATE($A20,12*$E$4)) | L20: =IF($K20="","",IF($K20>MAX($A$8:$A$5007),"",IFERROR(MATCH($K20,$A$8:$A$5007,1),""))) | M20: =IF($L20="","",INDEX($A$8:$A$5007,$L20)) | N20: =IF($L20="","",INDEX($B$8:$B$5007,$L20)) | O20: =IF($M20="","",IF($K20-$M20>7,"",IF($M20<=$A20,"",IF(OR($B20<=0,$N20<=0),"",($N20/$B20)^(365/($M20-$A20))-1)))) | P20: =IF($B20="","",IF($P19="",$B20,MAX($P19,$B20))) | Q20: =IF($P20="","",$B20/$P20-1)
K21: =IF($A21="","",EDATE($A21,12*$E$4)) | L21: =IF($K21="","",IF($K21>MAX($A$8:$A$5007),"",IFERROR(MATCH($K21,$A$8:$A$5007,1),""))) | M21: =IF($L21="","",INDEX($A$8:$A$5007,$L21)) | N21: =IF($L21="","",INDEX($B$8:$B$5007,$L21)) | O21: =IF($M21="","",IF($K21-$M21>7,"",IF($M21<=$A21,"",IF(OR($B21<=0,$N21<=0),"",($N21/$B21)^(365/($M21-$A21))-1)))) | P21: =IF($B21="","",IF($P20="",$B21,MAX($P20,$B21))) | Q21: =IF($P21="","",$B21/$P21-1)
D22: The fund over your own dates | K22: =IF($A22="","",EDATE($A22,12*$E$4)) | L22: =IF($K22="","",IF($K22>MAX($A$8:$A$5007),"",IFERROR(MATCH($K22,$A$8:$A$5007,1),""))) | M22: =IF($L22="","",INDEX($A$8:$A$5007,$L22)) | N22: =IF($L22="","",INDEX($B$8:$B$5007,$L22)) | O22: =IF($M22="","",IF($K22-$M22>7,"",IF($M22<=$A22,"",IF(OR($B22<=0,$N22<=0),"",($N22/$B22)^(365/($M22-$A22))-1)))) | P22: =IF($B22="","",IF($P21="",$B22,MAX($P21,$B22))) | Q22: =IF($P22="","",$B22/$P22-1)
D23: From the NAV on or before your first payment | E23: =IF(OR(Calc!$D$8=0,Calc!$D$1=0,COUNT($B$8:$B$5007)<2),"",IF(AND(Calc!$D$8>=MIN($A$8:$A$5007),Calc!$D$8<=MAX($A$8:$A$5007),Calc!$D$9<=MAX($A$8:$A$5007)+7),INDEX($A$8:$A$5007,MATCH(Calc!$D$8,$A$8:$A$5007,1)),"")) | K23: =IF($A23="","",EDATE($A23,12*$E$4)) | L23: =IF($K23="","",IF($K23>MAX($A$8:$A$5007),"",IFERROR(MATCH($K23,$A$8:$A$5007,1),""))) | M23: =IF($L23="","",INDEX($A$8:$A$5007,$L23)) | N23: =IF($L23="","",INDEX($B$8:$B$5007,$L23)) | O23: =IF($M23="","",IF($K23-$M23>7,"",IF($M23<=$A23,"",IF(OR($B23<=0,$N23<=0),"",($N23/$B23)^(365/($M23-$A23))-1)))) | P23: =IF($B23="","",IF($P22="",$B23,MAX($P22,$B23))) | Q23: =IF($P23="","",$B23/$P23-1)
D24: To the NAV on or before your Worth today date | E24: =IF(OR(Calc!$D$8=0,Calc!$D$1=0,COUNT($B$8:$B$5007)<2),"",IF(AND(Calc!$D$8>=MIN($A$8:$A$5007),Calc!$D$8<=MAX($A$8:$A$5007),Calc!$D$9<=MAX($A$8:$A$5007)+7),INDEX($A$8:$A$5007,MATCH(Calc!$D$9,$A$8:$A$5007,1)),"")) | K24: =IF($A24="","",EDATE($A24,12*$E$4)) | L24: =IF($K24="","",IF($K24>MAX($A$8:$A$5007),"",IFERROR(MATCH($K24,$A$8:$A$5007,1),""))) | M24: =IF($L24="","",INDEX($A$8:$A$5007,$L24)) | N24: =IF($L24="","",INDEX($B$8:$B$5007,$L24)) | O24: =IF($M24="","",IF($K24-$M24>7,"",IF($M24<=$A24,"",IF(OR($B24<=0,$N24<=0),"",($N24/$B24)^(365/($M24-$A24))-1)))) | P24: =IF($B24="","",IF($P23="",$B24,MAX($P23,$B24))) | Q24: =IF($P24="","",$B24/$P24-1)
D25: The fund itself grew at, a year | E25: =IF(OR(Calc!$D$8=0,Calc!$D$1=0,COUNT($B$8:$B$5007)<2),"",IF(NOT(AND(Calc!$D$8>=MIN($A$8:$A$5007),Calc!$D$8<=MAX($A$8:$A$5007),Calc!$D$9<=MAX($A$8:$A$5007)+7)),"the NAV list does not cover your dates",IF($E$24<=$E$23,"",IFERROR((INDEX($B$8:$B$5007,MATCH($E$24,$A$8:$A$5007,0))/INDEX($B$8:$B$5007,MATCH($E$23,$A$8:$A$5007,0)))^(365/($E$24-$E$23))-1,"")))) | K25: =IF($A25="","",EDATE($A25,12*$E$4)) | L25: =IF($K25="","",IF($K25>MAX($A$8:$A$5007),"",IFERROR(MATCH($K25,$A$8:$A$5007,1),""))) | M25: =IF($L25="","",INDEX($A$8:$A$5007,$L25)) | N25: =IF($L25="","",INDEX($B$8:$B$5007,$L25)) | O25: =IF($M25="","",IF($K25-$M25>7,"",IF($M25<=$A25,"",IF(OR($B25<=0,$N25<=0),"",($N25/$B25)^(365/($M25-$A25))-1)))) | P25: =IF($B25="","",IF($P24="",$B25,MAX($P24,$B25))) | Q25: =IF($P25="","",$B25/$P25-1)
D26: Your money in it earned | E26: =IF(ISNUMBER($E$25),'My investments'!$B$4,"") | K26: =IF($A26="","",EDATE($A26,12*$E$4)) | L26: =IF($K26="","",IF($K26>MAX($A$8:$A$5007),"",IFERROR(MATCH($K26,$A$8:$A$5007,1),""))) | M26: =IF($L26="","",INDEX($A$8:$A$5007,$L26)) | N26: =IF($L26="","",INDEX($B$8:$B$5007,$L26)) | O26: =IF($M26="","",IF($K26-$M26>7,"",IF($M26<=$A26,"",IF(OR($B26<=0,$N26<=0),"",($N26/$B26)^(365/($M26-$A26))-1)))) | P26: =IF($B26="","",IF($P25="",$B26,MAX($P25,$B26))) | Q26: =IF($P26="","",$B26/$P26-1)
D27: The difference: your timing | E27: =IF(AND(ISNUMBER($E$25),ISNUMBER($E$26)),$E$26-$E$25,"") | K27: =IF($A27="","",EDATE($A27,12*$E$4)) | L27: =IF($K27="","",IF($K27>MAX($A$8:$A$5007),"",IFERROR(MATCH($K27,$A$8:$A$5007,1),""))) | M27: =IF($L27="","",INDEX($A$8:$A$5007,$L27)) | N27: =IF($L27="","",INDEX($B$8:$B$5007,$L27)) | O27: =IF($M27="","",IF($K27-$M27>7,"",IF($M27<=$A27,"",IF(OR($B27<=0,$N27<=0),"",($N27/$B27)^(365/($M27-$A27))-1)))) | P27: =IF($B27="","",IF($P26="",$B27,MAX($P26,$B27))) | Q27: =IF($P27="","",$B27/$P27-1)
D28: The fund's figure is what it would publish for exactly your dates, as if one lump sum had gone in on day one. The difference is the effect of when your money went in and out: a description of your dates, not a verdict. | K28: =IF($A28="","",EDATE($A28,12*$E$4)) | L28: =IF($K28="","",IF($K28>MAX($A$8:$A$5007),"",IFERROR(MATCH($K28,$A$8:$A$5007,1),""))) | M28: =IF($L28="","",INDEX($A$8:$A$5007,$L28)) | N28: =IF($L28="","",INDEX($B$8:$B$5007,$L28)) | O28: =IF($M28="","",IF($K28-$M28>7,"",IF($M28<=$A28,"",IF(OR($B28<=0,$N28<=0),"",($N28/$B28)^(365/($M28-$A28))-1)))) | P28: =IF($B28="","",IF($P27="",$B28,MAX($P27,$B28))) | Q28: =IF($P28="","",$B28/$P28-1)
K29: =IF($A29="","",EDATE($A29,12*$E$4)) | L29: =IF($K29="","",IF($K29>MAX($A$8:$A$5007),"",IFERROR(MATCH($K29,$A$8:$A$5007,1),""))) | M29: =IF($L29="","",INDEX($A$8:$A$5007,$L29)) | N29: =IF($L29="","",INDEX($B$8:$B$5007,$L29)) | O29: =IF($M29="","",IF($K29-$M29>7,"",IF($M29<=$A29,"",IF(OR($B29<=0,$N29<=0),"",($N29/$B29)^(365/($M29-$A29))-1)))) | P29: =IF($B29="","",IF($P28="",$B29,MAX($P28,$B29))) | Q29: =IF($P29="","",$B29/$P29-1)
D30: Your units today | K30: =IF($A30="","",EDATE($A30,12*$E$4)) | L30: =IF($K30="","",IF($K30>MAX($A$8:$A$5007),"",IFERROR(MATCH($K30,$A$8:$A$5007,1),""))) | M30: =IF($L30="","",INDEX($A$8:$A$5007,$L30)) | N30: =IF($L30="","",INDEX($B$8:$B$5007,$L30)) | O30: =IF($M30="","",IF($K30-$M30>7,"",IF($M30<=$A30,"",IF(OR($B30<=0,$N30<=0),"",($N30/$B30)^(365/($M30-$A30))-1)))) | P30: =IF($B30="","",IF($P29="",$B30,MAX($P29,$B30))) | Q30: =IF($P30="","",$B30/$P30-1)
D31: Latest NAV in the list | E31: =IF(COUNT($B$8:$B$5007)=0,"",INDEX($B$8:$B$5007,COUNT($B$8:$B$5007))) | K31: =IF($A31="","",EDATE($A31,12*$E$4)) | L31: =IF($K31="","",IF($K31>MAX($A$8:$A$5007),"",IFERROR(MATCH($K31,$A$8:$A$5007,1),""))) | M31: =IF($L31="","",INDEX($A$8:$A$5007,$L31)) | N31: =IF($L31="","",INDEX($B$8:$B$5007,$L31)) | O31: =IF($M31="","",IF($K31-$M31>7,"",IF($M31<=$A31,"",IF(OR($B31<=0,$N31<=0),"",($N31/$B31)^(365/($M31-$A31))-1)))) | P31: =IF($B31="","",IF($P30="",$B31,MAX($P30,$B31))) | Q31: =IF($P31="","",$B31/$P31-1)
D32: On | E32: =IF(COUNT($A$8:$A$5007)=0,"",MAX($A$8:$A$5007)) | K32: =IF($A32="","",EDATE($A32,12*$E$4)) | L32: =IF($K32="","",IF($K32>MAX($A$8:$A$5007),"",IFERROR(MATCH($K32,$A$8:$A$5007,1),""))) | M32: =IF($L32="","",INDEX($A$8:$A$5007,$L32)) | N32: =IF($L32="","",INDEX($B$8:$B$5007,$L32)) | O32: =IF($M32="","",IF($K32-$M32>7,"",IF($M32<=$A32,"",IF(OR($B32<=0,$N32<=0),"",($N32/$B32)^(365/($M32-$A32))-1)))) | P32: =IF($B32="","",IF($P31="",$B32,MAX($P31,$B32))) | Q32: =IF($P32="","",$B32/$P32-1)
D33: Your units are worth | E33: =IF(OR($E$6="",$E$31=""),"",$E$6*$E$31) | K33: =IF($A33="","",EDATE($A33,12*$E$4)) | L33: =IF($K33="","",IF($K33>MAX($A$8:$A$5007),"",IFERROR(MATCH($K33,$A$8:$A$5007,1),""))) | M33: =IF($L33="","",INDEX($A$8:$A$5007,$L33)) | N33: =IF($L33="","",INDEX($B$8:$B$5007,$L33)) | O33: =IF($M33="","",IF($K33-$M33>7,"",IF($M33<=$A33,"",IF(OR($B33<=0,$N33<=0),"",($N33/$B33)^(365/($M33-$A33))-1)))) | P33: =IF($B33="","",IF($P32="",$B33,MAX($P32,$B33))) | Q33: =IF($P33="","",$B33/$P33-1)
K34: =IF($A34="","",EDATE($A34,12*$E$4)) | L34: =IF($K34="","",IF($K34>MAX($A$8:$A$5007),"",IFERROR(MATCH($K34,$A$8:$A$5007,1),""))) | M34: =IF($L34="","",INDEX($A$8:$A$5007,$L34)) | N34: =IF($L34="","",INDEX($B$8:$B$5007,$L34)) | O34: =IF($M34="","",IF($K34-$M34>7,"",IF($M34<=$A34,"",IF(OR($B34<=0,$N34<=0),"",($N34/$B34)^(365/($M34-$A34))-1)))) | P34: =IF($B34="","",IF($P33="",$B34,MAX($P33,$B34))) | Q34: =IF($P34="","",$B34/$P34-1)
D35: Year by year | E35: Return | F35: From | G35: To | K35: =IF($A35="","",EDATE($A35,12*$E$4)) | L35: =IF($K35="","",IF($K35>MAX($A$8:$A$5007),"",IFERROR(MATCH($K35,$A$8:$A$5007,1),""))) | M35: =IF($L35="","",INDEX($A$8:$A$5007,$L35)) | N35: =IF($L35="","",INDEX($B$8:$B$5007,$L35)) | O35: =IF($M35="","",IF($K35-$M35>7,"",IF($M35<=$A35,"",IF(OR($B35<=0,$N35<=0),"",($N35/$B35)^(365/($M35-$A35))-1)))) | P35: =IF($B35="","",IF($P34="",$B35,MAX($P34,$B35))) | Q35: =IF($P35="","",$B35/$P35-1)
D36: =IF(COUNT($A$8:$A$5007)<2,"",YEAR(MIN($A$8:$A$5007))) | E36: =IF($D36="","",IF($G36<=$F36,"",INDEX($B$8:$B$5007,MATCH($G36,$A$8:$A$5007,0))/INDEX($B$8:$B$5007,MATCH($F36,$A$8:$A$5007,0))-1)) | F36: =IF($D36="","",IF($D36=YEAR(MIN($A$8:$A$5007)),MIN($A$8:$A$5007),INDEX($A$8:$A$5007,MATCH(DATE($D36-1,12,31),$A$8:$A$5007,1)))) | G36: =IF($D36="","",INDEX($A$8:$A$5007,MATCH(DATE($D36,12,31),$A$8:$A$5007,1))) | K36: =IF($A36="","",EDATE($A36,12*$E$4)) | L36: =IF($K36="","",IF($K36>MAX($A$8:$A$5007),"",IFERROR(MATCH($K36,$A$8:$A$5007,1),""))) | M36: =IF($L36="","",INDEX($A$8:$A$5007,$L36)) | N36: =IF($L36="","",INDEX($B$8:$B$5007,$L36)) | O36: =IF($M36="","",IF($K36-$M36>7,"",IF($M36<=$A36,"",IF(OR($B36<=0,$N36<=0),"",($N36/$B36)^(365/($M36-$A36))-1)))) | P36: =IF($B36="","",IF($P35="",$B36,MAX($P35,$B36))) | Q36: =IF($P36="","",$B36/$P36-1)
D37: =IF($D36="","",IF($D36+1>YEAR(MAX($A$8:$A$5007)),"",$D36+1)) | E37: =IF($D37="","",IF($G37<=$F37,"",INDEX($B$8:$B$5007,MATCH($G37,$A$8:$A$5007,0))/INDEX($B$8:$B$5007,MATCH($F37,$A$8:$A$5007,0))-1)) | F37: =IF($D37="","",IF($D37=YEAR(MIN($A$8:$A$5007)),MIN($A$8:$A$5007),INDEX($A$8:$A$5007,MATCH(DATE($D37-1,12,31),$A$8:$A$5007,1)))) | G37: =IF($D37="","",INDEX($A$8:$A$5007,MATCH(DATE($D37,12,31),$A$8:$A$5007,1))) | K37: =IF($A37="","",EDATE($A37,12*$E$4)) | L37: =IF($K37="","",IF($K37>MAX($A$8:$A$5007),"",IFERROR(MATCH($K37,$A$8:$A$5007,1),""))) | M37: =IF($L37="","",INDEX($A$8:$A$5007,$L37)) | N37: =IF($L37="","",INDEX($B$8:$B$5007,$L37)) | O37: =IF($M37="","",IF($K37-$M37>7,"",IF($M37<=$A37,"",IF(OR($B37<=0,$N37<=0),"",($N37/$B37)^(365/($M37-$A37))-1)))) | P37: =IF($B37="","",IF($P36="",$B37,MAX($P36,$B37))) | Q37: =IF($P37="","",$B37/$P37-1)
D38: =IF($D37="","",IF($D37+1>YEAR(MAX($A$8:$A$5007)),"",$D37+1)) | E38: =IF($D38="","",IF($G38<=$F38,"",INDEX($B$8:$B$5007,MATCH($G38,$A$8:$A$5007,0))/INDEX($B$8:$B$5007,MATCH($F38,$A$8:$A$5007,0))-1)) | F38: =IF($D38="","",IF($D38=YEAR(MIN($A$8:$A$5007)),MIN($A$8:$A$5007),INDEX($A$8:$A$5007,MATCH(DATE($D38-1,12,31),$A$8:$A$5007,1)))) | G38: =IF($D38="","",INDEX($A$8:$A$5007,MATCH(DATE($D38,12,31),$A$8:$A$5007,1))) | K38: =IF($A38="","",EDATE($A38,12*$E$4)) | L38: =IF($K38="","",IF($K38>MAX($A$8:$A$5007),"",IFERROR(MATCH($K38,$A$8:$A$5007,1),""))) | M38: =IF($L38="","",INDEX($A$8:$A$5007,$L38)) | N38: =IF($L38="","",INDEX($B$8:$B$5007,$L38)) | O38: =IF($M38="","",IF($K38-$M38>7,"",IF($M38<=$A38,"",IF(OR($B38<=0,$N38<=0),"",($N38/$B38)^(365/($M38-$A38))-1)))) | P38: =IF($B38="","",IF($P37="",$B38,MAX($P37,$B38))) | Q38: =IF($P38="","",$B38/$P38-1)
D39: =IF($D38="","",IF($D38+1>YEAR(MAX($A$8:$A$5007)),"",$D38+1)) | E39: =IF($D39="","",IF($G39<=$F39,"",INDEX($B$8:$B$5007,MATCH($G39,$A$8:$A$5007,0))/INDEX($B$8:$B$5007,MATCH($F39,$A$8:$A$5007,0))-1)) | F39: =IF($D39="","",IF($D39=YEAR(MIN($A$8:$A$5007)),MIN($A$8:$A$5007),INDEX($A$8:$A$5007,MATCH(DATE($D39-1,12,31),$A$8:$A$5007,1)))) | G39: =IF($D39="","",INDEX($A$8:$A$5007,MATCH(DATE($D39,12,31),$A$8:$A$5007,1))) | K39: =IF($A39="","",EDATE($A39,12*$E$4)) | L39: =IF($K39="","",IF($K39>MAX($A$8:$A$5007),"",IFERROR(MATCH($K39,$A$8:$A$5007,1),""))) | M39: =IF($L39="","",INDEX($A$8:$A$5007,$L39)) | N39: =IF($L39="","",INDEX($B$8:$B$5007,$L39)) | O39: =IF($M39="","",IF($K39-$M39>7,"",IF($M39<=$A39,"",IF(OR($B39<=0,$N39<=0),"",($N39/$B39)^(365/($M39-$A39))-1)))) | P39: =IF($B39="","",IF($P38="",$B39,MAX($P38,$B39))) | Q39: =IF($P39="","",$B39/$P39-1)
D40: =IF($D39="","",IF($D39+1>YEAR(MAX($A$8:$A$5007)),"",$D39+1)) | E40: =IF($D40="","",IF($G40<=$F40,"",INDEX($B$8:$B$5007,MATCH($G40,$A$8:$A$5007,0))/INDEX($B$8:$B$5007,MATCH($F40,$A$8:$A$5007,0))-1)) | F40: =IF($D40="","",IF($D40=YEAR(MIN($A$8:$A$5007)),MIN($A$8:$A$5007),INDEX($A$8:$A$5007,MATCH(DATE($D40-1,12,31),$A$8:$A$5007,1)))) | G40: =IF($D40="","",INDEX($A$8:$A$5007,MATCH(DATE($D40,12,31),$A$8:$A$5007,1))) | K40: =IF($A40="","",EDATE($A40,12*$E$4)) | L40: =IF($K40="","",IF($K40>MAX($A$8:$A$5007),"",IFERROR(MATCH($K40,$A$8:$A$5007,1),""))) | M40: =IF($L40="","",INDEX($A$8:$A$5007,$L40)) | N40: =IF($L40="","",INDEX($B$8:$B$5007,$L40)) | O40: =IF($M40="","",IF($K40-$M40>7,"",IF($M40<=$A40,"",IF(OR($B40<=0,$N40<=0),"",($N40/$B40)^(365/($M40-$A40))-1)))) | P40: =IF($B40="","",IF($P39="",$B40,MAX($P39,$B40))) | Q40: =IF($P40="","",$B40/$P40-1)
D41: =IF($D40="","",IF($D40+1>YEAR(MAX($A$8:$A$5007)),"",$D40+1)) | E41: =IF($D41="","",IF($G41<=$F41,"",INDEX($B$8:$B$5007,MATCH($G41,$A$8:$A$5007,0))/INDEX($B$8:$B$5007,MATCH($F41,$A$8:$A$5007,0))-1)) | F41: =IF($D41="","",IF($D41=YEAR(MIN($A$8:$A$5007)),MIN($A$8:$A$5007),INDEX($A$8:$A$5007,MATCH(DATE($D41-1,12,31),$A$8:$A$5007,1)))) | G41: =IF($D41="","",INDEX($A$8:$A$5007,MATCH(DATE($D41,12,31),$A$8:$A$5007,1))) | K41: =IF($A41="","",EDATE($A41,12*$E$4)) | L41: =IF($K41="","",IF($K41>MAX($A$8:$A$5007),"",IFERROR(MATCH($K41,$A$8:$A$5007,1),""))) | M41: =IF($L41="","",INDEX($A$8:$A$5007,$L41)) | N41: =IF($L41="","",INDEX($B$8:$B$5007,$L41)) | O41: =IF($M41="","",IF($K41-$M41>7,"",IF($M41<=$A41,"",IF(OR($B41<=0,$N41<=0),"",($N41/$B41)^(365/($M41-$A41))-1)))) | P41: =IF($B41="","",IF($P40="",$B41,MAX($P40,$B41))) | Q41: =IF($P41="","",$B41/$P41-1)
...

Sheet Example
B2: Fund or portfolio name | C2: An example, already filled in | H2: The example's answers
B3: Your XIRR | H3: You put in | I3: =SUMIF($C$8:$C$10,"Money in",$D$8:$D$10) -> 200000
B4: =IFERROR(XIRR($E$8:$E$10,$B$8:$B$10),IFERROR(XIRR($E$8:$E$10,$B$8:$B$10,-0.5),"Check the entries")) -> 0.13401346 | H4: Worth now | I4: =SUMIF($C$8:$C$10,"Worth today",$D$8:$D$10) -> 242000
H5: Gain | I5: =$I$4-$I$3 -> 42000
B6: Two payments a year apart and the holding's worth a year after the second. Total return 21%; XIRR 13.4% a year, because the second rupee was invested for only one of the two years. Real return at 6% inflation: (1.134 ÷ 1.06) − 1 = 7.0%, not 7.4%. | H6: Total return | I6: =$I$5/$I$3 -> 0.21
B7: Date | C7: What happened | D7: Amount | E7: Used by the sheet | F7: Which holding | H7: XIRR | I7: =$B$4 -> 0.13401346
B8: 44197 | C8: Money in | D8: 100000 | E8: =IF($B8="","",IF($C8="Money in",-$D8,$D8)) -> -100000 | H8: Doubling time at that rate | I8: =LN(2)/LN(1+$B$4) -> 5.5115316
B9: 44562 | C9: Money in | D9: 100000 | E9: =IF($B9="","",IF($C9="Money in",-$D9,$D9)) -> -100000 | H9: Real return at 6% inflation | I9: =(1+$B$4)/1.06-1 -> 0.069824022
B10: 44927 | C10: Worth today | D10: 242000 | E10: =IF($B10="","",IF($C10="Money in",-$D10,$D10)) -> 242000
H11: The site works this example out the same way; its About page sets out how, under How this tool calculates.

Sheet About
B2: Where You Stand: XIRR Calculator, version 3.0
B4: It works with no internet connection, and nothing in it connects to anything. No macros, no add-ins: plain formulas that Excel and Google Sheets evaluate themselves.
B6: This is an educational tool for readers. Every figure is before exit load and before tax. It measures money that has already moved and illustrates assumptions you choose yourself; it does not recommend, rate or rank anything.
B8: The tabs are protected without a password. To adapt this sheet, choose Review, then Unprotect Sheet. The hidden Calc tab carries the working; unhide it to inspect every step.
B10: Conventions: XIRR on a 365-day year, the same as a spreadsheet's XIRR and the site; rolling windows end on the same calendar date, or the last value up to seven days before it; real return is (1 + return) ÷ (1 + inflation) − 1; monthly instalments are added at the start of each month and the step-up applies once a year.
B12: The site and this sheet give the same answers for the same entries; both were checked against each other and against independent calculations.
B14: No Excel? Upload this file to Google Sheets and it works there too, unchanged.

Sheet Calc
C1: Rows marked Worth today | D1: =COUNTIFS('My investments'!$C$8:$C$507,"Worth today",'My investments'!$B$8:$B$507,"<>") -> 0 | F1: annual rate r | G1: =IF('Plan my goal'!$B$8="",0,'Plan my goal'!$B$8/100) -> 0.1
F2: monthly rate i | G2: =(1+$G$1)^(1/12)-1 -> 0.0079741404
C3: Total invested | D3: =SUMIFS('My investments'!$D$8:$D$507,'My investments'!$C$8:$C$507,"Money in",'My investments'!$B$8:$B$507,"<>") -> 0 | F3: one year of 1/month | G3: =IF($G$2=0,12,(((1+$G$2)^12-1)/$G$2)*(1+$G$2)) -> 12.640537
C4: Total withdrawn | D4: =SUMIFS('My investments'!$D$8:$D$507,'My investments'!$C$8:$C$507,"Money out",'My investments'!$B$8:$B$507,"<>") -> 0 | F4: years Y | G4: =IF('Plan my goal'!$B$6="",0,'Plan my goal'!$B$6) -> 15
C5: Worth today | D5: =SUMIFS('My investments'!$D$8:$D$507,'My investments'!$C$8:$C$507,"Worth today",'My investments'!$B$8:$B$507,"<>") -> 0 | F5: step-up g | G5: =IF('Plan my goal'!$B$9="",0,'Plan my goal'!$B$9/100) -> 0 | I5: =IF($G$5>0.1,$G$5,0.1) -> 0.1
C6: Amount without a date | D6: =SUMPRODUCT(('My investments'!$B$8:$B$507="")*('My investments'!$D$8:$D$507<>"")) -> 0 | F6: ratio x | G6: =(1+$G$5)/(1+$G$1) -> 0.90909091 | I6: =(1+$I$5)/(1+$G$1) -> 1 | X6: fund flow | Y6: date | Z6: index flow | AA6: holding 1 | AB6: holding 2 | AC6: holding 3 | AD6: holding 4 | AE6: holding 5 | AF6: holding 6 | AG6: holding 7 | AH6: holding 8 | AI6: holding 9 | AJ6: holding 10 | AL6: index value that day | AM6: index units
C7: Date without an amount | D7: =SUMPRODUCT(('My investments'!$B$8:$B$507<>"")*('My investments'!$D$8:$D$507="")) -> 0 | F7: geometric sum S | G7: =IF($G$4<=0,0,IF(ABS($G$6-1)<0.000000000001,$G$4,(1-$G$6^$G$4)/(1-$G$6))) -> 8.3666875 | I7: =IF($G$4<=0,0,IF(ABS($I$6-1)<0.000000000001,$G$4,(1-$I$6^$G$4)/(1-$I$6))) -> 15 | X7: 0 | Y7: =$D$8 -> 0 | Z7: 0 | AA7: 0 | AB7: 0 | AC7: 0 | AD7: 0 | AE7: 0 | AF7: 0 | AG7: 0 | AH7: 0 | AI7: 0 | AJ7: 0
C8: First date | D8: =IF(COUNT('My investments'!$B$8:$B$507)=0,0,MIN('My investments'!$B$8:$B$507)) -> 0 | F8: growth of 1/month | G8: =IF($G$4<=0,0,$G$3*(1+$G$1)^($G$4-1)*$G$7) -> 401.62122 | I8: =IF($G$4<=0,0,$G$3*(1+$G$1)^($G$4-1)*$I$7) -> 720.03625 | X8: =IF('My investments'!$B8="",0,IF('My investments'!$E8="",0,'My investments'!$E8)) -> 0 | Y8: =IF('My investments'!$B8="",$D$8,'My investments'!$B8) -> 0 | Z8: =IF('My investments'!$C8="Worth today",0,$X8) -> 0 | AA8: =IF('My investments'!$H$15="",0,IF('My investments'!$F8='My investments'!$H$15,$X8,0)) -> 0 | AB8: =IF('My investments'!$H$16="",0,IF('My investments'!$F8='My investments'!$H$16,$X8,0)) -> 0 | AC8: =IF('My investments'!$H$17="",0,IF('My investments'!$F8='My investments'!$H$17,$X8,0)) -> 0 | AD8: =IF('My investments'!$H$18="",0,IF('My investments'!$F8='My investments'!$H$18,$X8,0)) -> 0 | AE8: =IF('My investments'!$H$19="",0,IF('My investments'!$F8='My investments'!$H$19,$X8,0)) -> 0 | AF8: =IF('My investments'!$H$20="",0,IF('My investments'!$F8='My investments'!$H$20,$X8,0)) -> 0 | AG8: =IF('My investments'!$H$21="",0,IF('My investments'!$F8='My investments'!$H$21,$X8,0)) -> 0 | AH8: =IF('My investments'!$H$22="",0,IF('My investments'!$F8='My investments'!$H$22,$X8,0)) -> 0 | AI8: =IF('My investments'!$H$23="",0,IF('My investments'!$F8='My investments'!$H$23,$X8,0)) -> 0 | AJ8: =IF('My investments'!$H$24="",0,IF('My investments'!$F8='My investments'!$H$24,$X8,0)) -> 0 | AL8: =IF('My investments'!$B8="","",IF($D$10=0,"",IFERROR(INDEX('Index history'!$B$8:$B$5007,MATCH('My investments'!$B8,'Index history'!$A$8:$A$5007,1)),""))) | AM8: =IF($AL8="",0,IF('My investments'!$D8="",0,IF('My investments'!$C8="Money in",'My investments'!$D8/$AL8,IF('My investments'!$C8="Money out",-'My investments'!$D8/$AL8,0)))) -> 0
C9: Valuation date (last Worth today row) | D9: =IF($D$1=0,$D$8,SUMPRODUCT(MAX(('My investments'!$C$8:$C$507="Worth today")*('My investments'!$B$8:$B$507)))) -> 0 | X9: =IF('My investments'!$B9="",0,IF('My investments'!$E9="",0,'My investments'!$E9)) -> 0 | Y9: =IF('My investments'!$B9="",$D$8,'My investments'!$B9) -> 0 | Z9: =IF('My investments'!$C9="Worth today",0,$X9) -> 0 | AA9: =IF('My investments'!$H$15="",0,IF('My investments'!$F9='My investments'!$H$15,$X9,0)) -> 0 | AB9: =IF('My investments'!$H$16="",0,IF('My investments'!$F9='My investments'!$H$16,$X9,0)) -> 0 | AC9: =IF('My investments'!$H$17="",0,IF('My investments'!$F9='My investments'!$H$17,$X9,0)) -> 0 | AD9: =IF('My investments'!$H$18="",0,IF('My investments'!$F9='My investments'!$H$18,$X9,0)) -> 0 | AE9: =IF('My investments'!$H$19="",0,IF('My investments'!$F9='My investments'!$H$19,$X9,0)) -> 0 | AF9: =IF('My investments'!$H$20="",0,IF('My investments'!$F9='My investments'!$H$20,$X9,0)) -> 0 | AG9: =IF('My investments'!$H$21="",0,IF('My investments'!$F9='My investments'!$H$21,$X9,0)) -> 0 | AH9: =IF('My investments'!$H$22="",0,IF('My investments'!$F9='My investments'!$H$22,$X9,0)) -> 0 | AI9: =IF('My investments'!$H$23="",0,IF('My investments'!$F9='My investments'!$H$23,$X9,0)) -> 0 | AJ9: =IF('My investments'!$H$24="",0,IF('My investments'!$F9='My investments'!$H$24,$X9,0)) -> 0 | AL9: =IF('My investments'!$B9="","",IF($D$10=0,"",IFERROR(INDEX('Index history'!$B$8:$B$5007,MATCH('My investments'!$B9,'Index history'!$A$8:$A$5007,1)),""))) | AM9: =IF($AL9="",0,IF('My investments'!$D9="",0,IF('My investments'!$C9="Money in",'My investments'!$D9/$AL9,IF('My investments'!$C9="Money out",-'My investments'!$D9/$AL9,0)))) -> 0
C10: Index rows | D10: =COUNT('Index history'!$A$8:$A$5007) -> 0 | F10: inputs usable? | G10: =IF('Plan my goal'!$B$6="",0,IF('Plan my goal'!$B$6<1,0,IF('Plan my goal'!$B$6>50,0,IF('Plan my goal'!$B$6<>INT('Plan my goal'!$B$6),0,IF('Plan my goal'!$B$4="",0,IF('Plan my goal'!$B$4<=0,0,IF('Plan my goal'!$B$8="",0,IF('Plan my goal'!$B$8<0,0,IF('Plan my goal'!$B$8>50,0,1))))))))) -> 1 | X10: =IF('My investments'!$B10="",0,IF('My investments'!$E10="",0,'My investments'!$E10)) -> 0 | Y10: =IF('My investments'!$B10="",$D$8,'My investments'!$B10) -> 0 | Z10: =IF('My investments'!$C10="Worth today",0,$X10) -> 0 | AA10: =IF('My investments'!$H$15="",0,IF('My investments'!$F10='My investments'!$H$15,$X10,0)) -> 0 | AB10: =IF('My investments'!$H$16="",0,IF('My investments'!$F10='My investments'!$H$16,$X10,0)) -> 0 | AC10: =IF('My investments'!$H$17="",0,IF('My investments'!$F10='My investments'!$H$17,$X10,0)) -> 0 | AD10: =IF('My investments'!$H$18="",0,IF('My investments'!$F10='My investments'!$H$18,$X10,0)) -> 0 | AE10: =IF('My investments'!$H$19="",0,IF('My investments'!$F10='My investments'!$H$19,$X10,0)) -> 0 | AF10: =IF('My investments'!$H$20="",0,IF('My investments'!$F10='My investments'!$H$20,$X10,0)) -> 0 | AG10: =IF('My investments'!$H$21="",0,IF('My investments'!$F10='My investments'!$H$21,$X10,0)) -> 0 | AH10: =IF('My investments'!$H$22="",0,IF('My investments'!$F10='My investments'!$H$22,$X10,0)) -> 0 | AI10: =IF('My investments'!$H$23="",0,IF('My investments'!$F10='My investments'!$H$23,$X10,0)) -> 0 | AJ10: =IF('My investments'!$H$24="",0,IF('My investments'!$F10='My investments'!$H$24,$X10,0)) -> 0 | AL10: =IF('My investments'!$B10="","",IF($D$10=0,"",IFERROR(INDEX('Index history'!$B$8:$B$5007,MATCH('My investments'!$B10,'Index history'!$A$8:$A$5007,1)),""))) | AM10: =IF($AL10="",0,IF('My investments'!$D10="",0,IF('My investments'!$C10="Money in",'My investments'!$D10/$AL10,IF('My investments'!$C10="Money out",-'My investments'!$D10/$AL10,0)))) -> 0
C11: Index last date | D11: =IF($D$10=0,0,MAX('Index history'!$A$8:$A$5007)) -> 0 | F11: from what you have | G11: =IF('Plan my goal'!$B$5="",0,'Plan my goal'!$B$5)*(1+$G$1)^$G$4 -> 1670899.3 | X11: =IF('My investments'!$B11="",0,IF('My investments'!$E11="",0,'My investments'!$E11)) -> 0 | Y11: =IF('My investments'!$B11="",$D$8,'My investments'!$B11) -> 0 | Z11: =IF('My investments'!$C11="Worth today",0,$X11) -> 0 | AA11: =IF('My investments'!$H$15="",0,IF('My investments'!$F11='My investments'!$H$15,$X11,0)) -> 0 | AB11: =IF('My investments'!$H$16="",0,IF('My investments'!$F11='My investments'!$H$16,$X11,0)) -> 0 | AC11: =IF('My investments'!$H$17="",0,IF('My investments'!$F11='My investments'!$H$17,$X11,0)) -> 0 | AD11: =IF('My investments'!$H$18="",0,IF('My investments'!$F11='My investments'!$H$18,$X11,0)) -> 0 | AE11: =IF('My investments'!$H$19="",0,IF('My investments'!$F11='My investments'!$H$19,$X11,0)) -> 0 | AF11: =IF('My investments'!$H$20="",0,IF('My investments'!$F11='My investments'!$H$20,$X11,0)) -> 0 | AG11: =IF('My investments'!$H$21="",0,IF('My investments'!$F11='My investments'!$H$21,$X11,0)) -> 0 | AH11: =IF('My investments'!$H$22="",0,IF('My investments'!$F11='My investments'!$H$22,$X11,0)) -> 0 | AI11: =IF('My investments'!$H$23="",0,IF('My investments'!$F11='My investments'!$H$23,$X11,0)) -> 0 | AJ11: =IF('My investments'!$H$24="",0,IF('My investments'!$F11='My investments'!$H$24,$X11,0)) -> 0 | AL11: =IF('My investments'!$B11="","",IF($D$10=0,"",IFERROR(INDEX('Index history'!$B$8:$B$5007,MATCH('My investments'!$B11,'Index history'!$A$8:$A$5007,1)),""))) | AM11: =IF($AL11="",0,IF('My investments'!$D11="",0,IF('My investments'!$C11="Money in",'My investments'!$D11/$AL11,IF('My investments'!$C11="Money out",-'My investments'!$D11/$AL11,0)))) -> 0
C12: Payment dates outside the index | D12: =IF($D$10=0,0,SUMPRODUCT(('My investments'!$B$8:$B$507<>"")*('My investments'!$C$8:$C$507<>"Worth today")*(('My investments'!$B$8:$B$507<$D$15)+('My investments'!$B$8:$B$507>$D$11)>0))) -> 0 | F12: from monthly | G12: =IF('Plan my goal'!$B$7="",0,'Plan my goal'!$B$7)*$G$8 -> 4016212.2 | X12: =IF('My investments'!$B12="",0,IF('My investments'!$E12="",0,'My investments'!$E12)) -> 0 | Y12: =IF('My investments'!$B12="",$D$8,'My investments'!$B12) -> 0 | Z12: =IF('My investments'!$C12="Worth today",0,$X12) -> 0 | AA12: =IF('My investments'!$H$15="",0,IF('My investments'!$F12='My investments'!$H$15,$X12,0)) -> 0 | AB12: =IF('My investments'!$H$16="",0,IF('My investments'!$F12='My investments'!$H$16,$X12,0)) -> 0 | AC12: =IF('My investments'!$H$17="",0,IF('My investments'!$F12='My investments'!$H$17,$X12,0)) -> 0 | AD12: =IF('My investments'!$H$18="",0,IF('My investments'!$F12='My investments'!$H$18,$X12,0)) -> 0 | AE12: =IF('My investments'!$H$19="",0,IF('My investments'!$F12='My investments'!$H$19,$X12,0)) -> 0 | AF12: =IF('My investments'!$H$20="",0,IF('My investments'!$F12='My investments'!$H$20,$X12,0)) -> 0 | AG12: =IF('My investments'!$H$21="",0,IF('My investments'!$F12='My investments'!$H$21,$X12,0)) -> 0 | AH12: =IF('My investments'!$H$22="",0,IF('My investments'!$F12='My investments'!$H$22,$X12,0)) -> 0 | AI12: =IF('My investments'!$H$23="",0,IF('My investments'!$F12='My investments'!$H$23,$X12,0)) -> 0 | AJ12: =IF('My investments'!$H$24="",0,IF('My investments'!$F12='My investments'!$H$24,$X12,0)) -> 0 | AL12: =IF('My investments'!$B12="","",IF($D$10=0,"",IFERROR(INDEX('Index history'!$B$8:$B$5007,MATCH('My investments'!$B12,'Index history'!$A$8:$A$5007,1)),""))) | AM12: =IF($AL12="",0,IF('My investments'!$D12="",0,IF('My investments'!$C12="Money in",'My investments'!$D12/$AL12,IF('My investments'!$C12="Money out",-'My investments'!$D12/$AL12,0)))) -> 0
C13: Net index units | D13: =SUM($AM$8:$AM$507) -> 0 | F13: gap | G13: =IF('Plan my goal'!$B$4="",0,'Plan my goal'!$B$4)-($G$11+$G$12) -> 4312888.6 | X13: =IF('My investments'!$B13="",0,IF('My investments'!$E13="",0,'My investments'!$E13)) -> 0 | Y13: =IF('My investments'!$B13="",$D$8,'My investments'!$B13) -> 0 | Z13: =IF('My investments'!$C13="Worth today",0,$X13) -> 0 | AA13: =IF('My investments'!$H$15="",0,IF('My investments'!$F13='My investments'!$H$15,$X13,0)) -> 0 | AB13: =IF('My investments'!$H$16="",0,IF('My investments'!$F13='My investments'!$H$16,$X13,0)) -> 0 | AC13: =IF('My investments'!$H$17="",0,IF('My investments'!$F13='My investments'!$H$17,$X13,0)) -> 0 | AD13: =IF('My investments'!$H$18="",0,IF('My investments'!$F13='My investments'!$H$18,$X13,0)) -> 0 | AE13: =IF('My investments'!$H$19="",0,IF('My investments'!$F13='My investments'!$H$19,$X13,0)) -> 0 | AF13: =IF('My investments'!$H$20="",0,IF('My investments'!$F13='My investments'!$H$20,$X13,0)) -> 0 | AG13: =IF('My investments'!$H$21="",0,IF('My investments'!$F13='My investments'!$H$21,$X13,0)) -> 0 | AH13: =IF('My investments'!$H$22="",0,IF('My investments'!$F13='My investments'!$H$22,$X13,0)) -> 0 | AI13: =IF('My investments'!$H$23="",0,IF('My investments'!$F13='My investments'!$H$23,$X13,0)) -> 0 | AJ13: =IF('My investments'!$H$24="",0,IF('My investments'!$F13='My investments'!$H$24,$X13,0)) -> 0 | AL13: =IF('My investments'!$B13="","",IF($D$10=0,"",IFERROR(INDEX('Index history'!$B$8:$B$5007,MATCH('My investments'!$B13,'Index history'!$A$8:$A$5007,1)),""))) | AM13: =IF($AL13="",0,IF('My investments'!$D13="",0,IF('My investments'!$C13="Money in",'My investments'!$D13/$AL13,IF('My investments'!$C13="Money out",-'My investments'!$D13/$AL13,0)))) -> 0
C14: Index value on the valuation date | D14: =IF($D$10=0,0,IFERROR(INDEX('Index history'!$B$8:$B$5007,MATCH($D$9,'Index history'!$A$8:$A$5007,1)),0)) -> 0 | F14: extra each month | G14: =IF($G$13<=0.5,0,IF($G$8<=0,0,$G$13/$G$8)) -> 10738.697 | X14: =IF('My investments'!$B14="",0,IF('My investments'!$E14="",0,'My investments'!$E14)) -> 0 | Y14: =IF('My investments'!$B14="",$D$8,'My investments'!$B14) -> 0 | Z14: =IF('My investments'!$C14="Worth today",0,$X14) -> 0 | AA14: =IF('My investments'!$H$15="",0,IF('My investments'!$F14='My investments'!$H$15,$X14,0)) -> 0 | AB14: =IF('My investments'!$H$16="",0,IF('My investments'!$F14='My investments'!$H$16,$X14,0)) -> 0 | AC14: =IF('My investments'!$H$17="",0,IF('My investments'!$F14='My investments'!$H$17,$X14,0)) -> 0 | AD14: =IF('My investments'!$H$18="",0,IF('My investments'!$F14='My investments'!$H$18,$X14,0)) -> 0 | AE14: =IF('My investments'!$H$19="",0,IF('My investments'!$F14='My investments'!$H$19,$X14,0)) -> 0 | AF14: =IF('My investments'!$H$20="",0,IF('My investments'!$F14='My investments'!$H$20,$X14,0)) -> 0 | AG14: =IF('My investments'!$H$21="",0,IF('My investments'!$F14='My investments'!$H$21,$X14,0)) -> 0 | AH14: =IF('My investments'!$H$22="",0,IF('My investments'!$F14='My investments'!$H$22,$X14,0)) -> 0 | AI14: =IF('My investments'!$H$23="",0,IF('My investments'!$F14='My investments'!$H$23,$X14,0)) -> 0 | AJ14: =IF('My investments'!$H$24="",0,IF('My investments'!$F14='My investments'!$H$24,$X14,0)) -> 0 | AL14: =IF('My investments'!$B14="","",IF($D$10=0,"",IFERROR(INDEX('Index history'!$B$8:$B$5007,MATCH('My investments'!$B14,'Index history'!$A$8:$A$5007,1)),""))) | AM14: =IF($AL14="",0,IF('My investments'!$D14="",0,IF('My investments'!$C14="Money in",'My investments'!$D14/$AL14,IF('My investments'!$C14="Money out",-'My investments'!$D14/$AL14,0)))) -> 0
C15: Index first date | D15: =IF($D$10=0,0,MIN('Index history'!$A$8:$A$5007)) -> 0 | F15: own money paid in | G15: =IF('Plan my goal'!$B$7="",0,'Plan my goal'!$B$7)*12*IF($G$5=0,$G$4,((1+$G$5)^$G$4-1)/$G$5) -> 1800000 | X15: =IF('My investments'!$B15="",0,IF('My investments'!$E15="",0,'My investments'!$E15)) -> 0 | Y15: =IF('My investments'!$B15="",$D$8,'My investments'!$B15) -> 0 | Z15: =IF('My investments'!$C15="Worth today",0,$X15) -> 0 | AA15: =IF('My investments'!$H$15="",0,IF('My investments'!$F15='My investments'!$H$15,$X15,0)) -> 0 | AB15: =IF('My investments'!$H$16="",0,IF('My investments'!$F15='My investments'!$H$16,$X15,0)) -> 0 | AC15: =IF('My investments'!$H$17="",0,IF('My investments'!$F15='My investments'!$H$17,$X15,0)) -> 0 | AD15: =IF('My investments'!$H$18="",0,IF('My investments'!$F15='My investments'!$H$18,$X15,0)) -> 0 | AE15: =IF('My investments'!$H$19="",0,IF('My investments'!$F15='My investments'!$H$19,$X15,0)) -> 0 | AF15: =IF('My investments'!$H$20="",0,IF('My investments'!$F15='My investments'!$H$20,$X15,0)) -> 0 | AG15: =IF('My investments'!$H$21="",0,IF('My investments'!$F15='My investments'!$H$21,$X15,0)) -> 0 | AH15: =IF('My investments'!$H$22="",0,IF('My investments'!$F15='My investments'!$H$22,$X15,0)) -> 0 | AI15: =IF('My investments'!$H$23="",0,IF('My investments'!$F15='My investments'!$H$23,$X15,0)) -> 0 | AJ15: =IF('My investments'!$H$24="",0,IF('My investments'!$F15='My investments'!$H$24,$X15,0)) -> 0 | AL15: =IF('My investments'!$B15="","",IF($D$10=0,"",IFERROR(INDEX('Index history'!$B$8:$B$5007,MATCH('My investments'!$B15,'Index history'!$A$8:$A$5007,1)),""))) | AM15: =IF($AL15="",0,IF('My investments'!$D15="",0,IF('My investments'!$C15="Money in",'My investments'!$D15/$AL15,IF('My investments'!$C15="Money out",-'My investments'!$D15/$AL15,0)))) -> 0
C16: Valuation date beyond the index | D16: =IF($D$10=0,0,IF($D$9>$D$11+7,1,0)) -> 0 | F16: carry on | G16: =$G$11+$G$12 -> 5687111.4 | X16: =IF('My investments'!$B16="",0,IF('My investments'!$E16="",0,'My investments'!$E16)) -> 0 | Y16: =IF('My investments'!$B16="",$D$8,'My investments'!$B16) -> 0 | Z16: =IF('My investments'!$C16="Worth today",0,$X16) -> 0 | AA16: =IF('My investments'!$H$15="",0,IF('My investments'!$F16='My investments'!$H$15,$X16,0)) -> 0 | AB16: =IF('My investments'!$H$16="",0,IF('My investments'!$F16='My investments'!$H$16,$X16,0)) -> 0 | AC16: =IF('My investments'!$H$17="",0,IF('My investments'!$F16='My investments'!$H$17,$X16,0)) -> 0 | AD16: =IF('My investments'!$H$18="",0,IF('My investments'!$F16='My investments'!$H$18,$X16,0)) -> 0 | AE16: =IF('My investments'!$H$19="",0,IF('My investments'!$F16='My investments'!$H$19,$X16,0)) -> 0 | AF16: =IF('My investments'!$H$20="",0,IF('My investments'!$F16='My investments'!$H$20,$X16,0)) -> 0 | AG16: =IF('My investments'!$H$21="",0,IF('My investments'!$F16='My investments'!$H$21,$X16,0)) -> 0 | AH16: =IF('My investments'!$H$22="",0,IF('My investments'!$F16='My investments'!$H$22,$X16,0)) -> 0 | AI16: =IF('My investments'!$H$23="",0,IF('My investments'!$F16='My investments'!$H$23,$X16,0)) -> 0 | AJ16: =IF('My investments'!$H$24="",0,IF('My investments'!$F16='My investments'!$H$24,$X16,0)) -> 0 | AL16: =IF('My investments'!$B16="","",IF($D$10=0,"",IFERROR(INDEX('Index history'!$B$8:$B$5007,MATCH('My investments'!$B16,'Index history'!$A$8:$A$5007,1)),""))) | AM16: =IF($AL16="",0,IF('My investments'!$D16="",0,IF('My investments'!$C16="Money in",'My investments'!$D16/$AL16,IF('My investments'!$C16="Money out",-'My investments'!$D16/$AL16,0)))) -> 0
